Workbook

Sheet Index
B2: =Model!B2 -> Hindustan Uniliver Ltd
B3: =Model!B3 -> HINDUNILVR | 500696
B4: =Model!B4 -> Financial Statement & DCF Analysis
B6: Inputs
B7: Historical Financial Statement
B8: Market Data
B9: Assumptions
B11: Calculation & Analysis
B12: Income Statement
B13: Balance Sheet
B14: Cash Flow Statement
B15: Working Capital
B16: Depreciation Schedule
B17: Debt Schedule
B18: WACC
... B25: Comparables Analysis

Sheet Assumption
B2: =Model!B2 -> Hindustan Uniliver Ltd
B3: =Model!B3 -> HINDUNILVR | 500696
B4: =Model!B4 -> Financial Statement & DCF Analysis
B6: Company Name | C6: Hindustan Uniliver Ltd
B7: ISIN Code | C7: INE030A01027
B8: Sector Name | C8: Consumer Staples
B9: Industry | C9: FMCG
B10: Basic Industry | C10: Personal Products
B11: Exchange Name | C11: NSE: HINDUNILVR , BSE Code: 500696
B12: Website | C12: https://www.hul.co.in/
B13: Company Description | C13: Hindustan Unilever Limited (HUL) is a leading FMCG company in India. It is a subsidiary of Unilever and operates across various consumer categories. The company offers products in beauty, personal care, home care, foods, and beverages. HUL owns several well-known brands such as Dove, Lux, Surf Excel, and Horlicks. It has a strong presence across India with a wide distribution network.
B14: Current Market Price | C14: 1932
B16: Company data
B17: Particulars
B18: No of Outstanding shares | C18: Nos | D18: 1115507
B19: Face Value per share | C19: Rs. | D19: 1
B20: Current Market Price | C20: Rs. | D20: 1932
B21: Market Capitalisation | C21: Rs. | D21: 453941
B23: Assumptions
B24: Increase in Revenue growth rate | C24: % | D24: =Scenario!D8 -> 0.054486857
B25: Base Case | C25: % | D25: =Scenario!D8 -> 0.054486857
B26: Bull Case | C26: % | D26: =Scenario!D9 -> 0.15509286
B27: Base Case | C27: % | D27: =Scenario!D10 -> 0.019791263
B28: Perpetual Growth rate | C28: % | D28: =Model!C155 -> 0.065
B29: 5 year Bond yield rate | C29: % | D29: =WACC!D41 -> 0.0676
B30: Interest rate | C30: % | D30: =WACC!D36 -> 0.24825236
B31: WACC | C31: % | D31: =WACC!D47 -> 0.072571274

Sheet Model
B2: Hindustan Uniliver Ltd
B3: HINDUNILVR | 500696 | E3: Historical Period
B4: Financial Statement & DCF Analysis | E4: 2022 | F4: =E4+1 -> 2023 | G4: =F4+1 -> 2024 | H4: =G4+1 -> 2025 | I4: =H4+1 -> 2026 | J4: =I4+1 -> 2027 | K4: =J4+1 -> 2028 | L4: =K4+1 -> 2029 | M4: =L4+1 -> 2030 | ... S4: =R4+1 -> 2036
B5: MasterCheck | E5: =IF(E95=0,"Ok","Error") -> Ok | F5: =IF(F95=0,"Ok","Error") -> Ok | G5: =IF(G95=0,"Ok","Error") -> Ok | H5: =IF(H95=0,"Ok","Error") -> Ok | I5: =IF(I95=0,"Ok","Error") -> Ok | J5: =IF(J95=0,"Ok","Error") -> Ok | K5: =IF(K95=0,"Ok","Error") -> Ok | L5: =IF(L95=0,"Ok","Error") -> Ok | ... S5: =IF(S95=0,"Ok","Error") -> Ok
B6: All Values In Crores
B8: Ratio & Assumptions
B10: Live Scenario | D10: Units | E10: 1
B12: Revenue Growth | D12: % | E12: 0 | F12: =F29/E29-1 -> 0.15509286 | G12: =G29/F29-1 -> 0.021723341 | H12: =H29/G29-1 -> 0.019791263 | I12: =I29/H29-1 -> 0.021339966 | J12: {=CHOOSE(E10,Scenario!E8:N8,Scenario!E9:N9,Scenario!E10:N10 )} -> 0.054486857 | K12: 0.051217645 | L12: 0.048144587 | M12: 0.045255911 | N12: 0.042540557 | O12: 0.039988123 | P12: 0.037588836 | Q12: 0.035333506 | R12: 0.033213495 | S12: 0.031220686
B13: Cost of Good Sold (% of Revenue) | D13: % | E13: =-E30/E29 -> 0.49069519 | F13: =-F30/F29 -> 0.52353912 | G13: =-G30/G29 -> 0.48080651 | H13: =-H30/H29 -> 0.48443466 | I13: =-I30/I29 -> 0.49117392 | J13: =AVERAGE($E13:$I13) -> 0.49412988 | K13: =AVERAGE($E13:$I13) -> 0.49412988 | L13: =AVERAGE($E13:$I13) -> 0.49412988 | M13: =AVERAGE($E13:$I13) -> 0.49412988 | N13: =AVERAGE($E13:$I13) -> 0.49412988 | O13: =AVERAGE($E13:$I13) -> 0.49412988 | P13: =AVERAGE($E13:$I13) -> 0.49412988 | Q13: =AVERAGE($E13:$I13) -> 0.49412988 | ... S13: =AVERAGE($E13:$I13) -> 0.49412988
B14: Employee Benefits Expenses (% of Revenue) | D14: % | E14: =-E35/E29 -> 0.048526103 | F14: =-F35/F29 -> 0.047111258 | G14: =-G35/G29 -> 0.048613804 | H14: =-H35/H29 -> 0.048747643 | I14: =-I35/I29 -> 0.04924924 | J14: =AVERAGE($E14:$I14) -> 0.04844961 | K14: =AVERAGE($E14:$I14) -> 0.04844961 | L14: =AVERAGE($E14:$I14) -> 0.04844961 | M14: =AVERAGE($E14:$I14) -> 0.04844961 | N14: =AVERAGE($E14:$I14) -> 0.04844961 | O14: =AVERAGE($E14:$I14) -> 0.04844961 | P14: =AVERAGE($E14:$I14) -> 0.04844961 | Q14: =AVERAGE($E14:$I14) -> 0.04844961 | ... S14: =AVERAGE($E14:$I14) -> 0.04844961
B15: Other SG&A Expenses (% of Revenue) | D15: % | E15: =-E36/E29 -> 0.21563132 | F15: =-F36/F29 -> 0.19579069 | G15: =-G36/G29 -> 0.23368231 | H15: =-H36/H29 -> 0.23153942 | I15: =-I36/I29 -> 0.22606564 | J15: =AVERAGE($E15:$I15) -> 0.22054188 | K15: =AVERAGE($E15:$I15) -> 0.22054188 | L15: =AVERAGE($E15:$I15) -> 0.22054188 | M15: =AVERAGE($E15:$I15) -> 0.22054188 | N15: =AVERAGE($E15:$I15) -> 0.22054188 | O15: =AVERAGE($E15:$I15) -> 0.22054188 | P15: =AVERAGE($E15:$I15) -> 0.22054188 | Q15: =AVERAGE($E15:$I15) -> 0.22054188 | ... S15: =AVERAGE($E15:$I15) -> 0.22054188
B16: Depreciation & Amortisation Expenses (% of PPE) | D16: % | E16: 0 | F16: =-F39/F139 -> 0.18430864 | G16: =-G39/G139 -> 0.17498921 | H16: =-H39/H139 -> 0.16872121 | I16: =-I39/I139 -> 0.15455072 | J16: =AVERAGE($E16:$I16) -> 0.13651396 | K16: =AVERAGE($E16:$I16) -> 0.13651396 | L16: =AVERAGE($E16:$I16) -> 0.13651396 | M16: =AVERAGE($E16:$I16) -> 0.13651396 | N16: =AVERAGE($E16:$I16) -> 0.13651396 | O16: =AVERAGE($E16:$I16) -> 0.13651396 | P16: =AVERAGE($E16:$I16) -> 0.13651396 | Q16: =AVERAGE($E16:$I16) -> 0.13651396 | ... S16: =AVERAGE($E16:$I16) -> 0.13651396
B17: Interest (% of Debt) | D17: % | E17: 0 | F17: =-F42/F145 -> 0.1093001 | G17: =-G42/G145 -> 0.27399508 | H17: =-H42/H145 -> 0.26617251 | I17: =-I42/I145 -> 0.24878641 | J17: =AVERAGE($E17:$I17) -> 0.17965082 | K17: =AVERAGE($E17:$I17) -> 0.17965082 | L17: =AVERAGE($E17:$I17) -> 0.17965082 | M17: =AVERAGE($E17:$I17) -> 0.17965082 | N17: =AVERAGE($E17:$I17) -> 0.17965082 | O17: =AVERAGE($E17:$I17) -> 0.17965082 | P17: =AVERAGE($E17:$I17) -> 0.17965082 | Q17: =AVERAGE($E17:$I17) -> 0.17965082 | ... S17: =AVERAGE($E17:$I17) -> 0.17965082
B18: Other Income (% of Revenue) | D18: % | E18: =E43/E29 -> 0.0049193456 | F18: =F43/F29 -> 0.0084516342 | G18: =G43/G29 -> 0.013102624 | H18: =H43/H29 -> 0.016111912 | I18: =I43/I29 -> 0.01164919 | J18: =AVERAGE($E18:$I18) -> 0.010846941 | K18: =AVERAGE($E18:$I18) -> 0.010846941 | L18: =AVERAGE($E18:$I18) -> 0.010846941 | M18: =AVERAGE($E18:$I18) -> 0.010846941 | N18: =AVERAGE($E18:$I18) -> 0.010846941 | O18: =AVERAGE($E18:$I18) -> 0.010846941 | P18: =AVERAGE($E18:$I18) -> 0.010846941 | Q18: =AVERAGE($E18:$I18) -> 0.010846941 | ... S18: =AVERAGE($E18:$I18) -> 0.010846941
B19: Tax Rate (% of Earning Before Tax) | D19: % | E19: =-E50/E49 -> 0.25113694 | F19: =-F50/F49 -> 0.23994005 | G19: =-G50/G49 -> 0.26166882 | H19: =-H50/H49 -> 0.25972945 | I19: =-I50/I49 -> 0.22878656 | J19: =AVERAGE($E19:$I19) -> 0.24825236 | K19: =AVERAGE($E19:$I19) -> 0.24825236 | L19: =AVERAGE($E19:$I19) -> 0.24825236 | M19: =AVERAGE($E19:$I19) -> 0.24825236 | N19: =AVERAGE($E19:$I19) -> 0.24825236 | O19: =AVERAGE($E19:$I19) -> 0.24825236 | P19: =AVERAGE($E19:$I19) -> 0.24825236 | Q19: =AVERAGE($E19:$I19) -> 0.24825236 | ... S19: =AVERAGE($E19:$I19) -> 0.24825236
B20: Divident Payout | D20: % | E20: =-E120/E54 -> 0.84637877 | F20: =-F120/F54 -> 0.83545302 | G20: =-G120/G54 -> 0.91577514 | H20: =-H120/H54 -> 1.1688689 | I20: =-I120/I54 -> 0.95043184 | J20: =AVERAGE($E20:$I20) -> 0.94338153 | K20: =AVERAGE($E20:$I20) -> 0.94338153 | L20: =AVERAGE($E20:$I20) -> 0.94338153 | M20: =AVERAGE($E20:$I20) -> 0.94338153 | N20: =AVERAGE($E20:$I20) -> 0.94338153 | O20: =AVERAGE($E20:$I20) -> 0.94338153 | P20: =AVERAGE($E20:$I20) -> 0.94338153 | Q20: =AVERAGE($E20:$I20) -> 0.94338153 | ... S20: =AVERAGE($E20:$I20) -> 0.94338153
B21: Account Receivable | D21: Days | E21: =E62/E29*365 -> 15.56153 | F21: =F62/F29*365 -> 18.551255 | G21: =G62/G29*365 -> 17.673275 | H21: =H62/H29*365 -> 22.083538 | I21: =I62/I29*365 -> 19.130964 | J21: =AVERAGE($E21:$I21) -> 18.600112 | K21: =AVERAGE($E21:$I21) -> 18.600112 | L21: =AVERAGE($E21:$I21) -> 18.600112 | M21: =AVERAGE($E21:$I21) -> 18.600112 | N21: =AVERAGE($E21:$I21) -> 18.600112 | O21: =AVERAGE($E21:$I21) -> 18.600112 | P21: =AVERAGE($E21:$I21) -> 18.600112 | Q21: =AVERAGE($E21:$I21) -> 18.600112 | ... S21: =AVERAGE($E21:$I21) -> 18.600112
B22: Inventory | D22: Days | E22: =-E63/E30*365 -> 58.093647 | F22: =-F63/F30*365 -> 48.922153 | G22: =-G63/G30*365 -> 49.328965 | H22: =-H63/H30*365 -> 52.700471 | I22: =-I63/I30*365 -> 55.202432 | J22: =AVERAGE($E22:$I22) -> 52.849533 | K22: =AVERAGE($E22:$I22) -> 52.849533 | L22: =AVERAGE($E22:$I22) -> 52.849533 | M22: =AVERAGE($E22:$I22) -> 52.849533 | N22: =AVERAGE($E22:$I22) -> 52.849533 | O22: =AVERAGE($E22:$I22) -> 52.849533 | P22: =AVERAGE($E22:$I22) -> 52.849533 | Q22: =AVERAGE($E22:$I22) -> 52.849533 | ... S22: =AVERAGE($E22:$I22) -> 52.849533
B23: Accounts Payable | D23: Days | E23: =-E78/E30*365 -> 128.61162 | F23: =-F78/F30*365 -> 110.1813 | G23: =-G78/G30*365 -> 128.60853 | H23: =-H78/H30*365 -> 135.06361 | I23: =-I78/I30*365 -> 153.59624 | J23: =AVERAGE($E23:$I23) -> 131.21226 | K23: =AVERAGE($E23:$I23) -> 131.21226 | L23: =AVERAGE($E23:$I23) -> 131.21226 | M23: =AVERAGE($E23:$I23) -> 131.21226 | N23: =AVERAGE($E23:$I23) -> 131.21226 | O23: =AVERAGE($E23:$I23) -> 131.21226 | P23: =AVERAGE($E23:$I23) -> 131.21226 | Q23: =AVERAGE($E23:$I23) -> 131.21226 | ... S23: =AVERAGE($E23:$I23) -> 131.21226
B24: Capital Assets Turnover Ratio | D24: Times | E24: =E29/E67 -> 8.50154 | F24: =F29/F67 -> 8.7178011 | G24: =G29/G67 -> 7.7071349 | H24: =H29/H67 -> 7.3183768 | I24: =I29/I67 -> 7.8792471 | J24: =I24-0.02 -> 7.8592471 | K24: =J24-0.02 -> 7.8392471 | L24: =K24-0.02 -> 7.8192471 | M24: =L24-0.02 -> 7.7992471 | N24: =M24-0.02 -> 7.7792471 | O24: =N24-0.02 -> 7.7592471 | P24: =O24-0.02 -> 7.7392471 | Q24: =P24-0.02 -> 7.7192471 | ... S24: =R24-0.02 -> 7.6792471
B26: Income Statement
B28: Income
B29: Revenue | E29: ='P&L'!D7 -> 52446 | F29: ='P&L'!E7 -> 60580 | G29: ='P&L'!F7 -> 61896 | H29: ='P&L'!G7 -> 63121 | I29: ='P&L'!H7 -> 64468 | J29: =I29*(1+J12) -> 67980.659 | K29: =J29*(1+K12) -> 71462.468 | L29: =K29*(1+L12) -> 74902.999 | M29: =L29*(1+M12) -> 78292.802 | N29: =M29*(1+N12) -> 81623.422 | O29: =N29*(1+O12) -> 84887.389 | P29: =O29*(1+P12) -> 88078.207 | Q29: =P29*(1+Q12) -> 91190.319 | ... S29: =R29*(1+S12) -> 97160.653
B30: Less: Cost of Goods Sold (COGS) | E30: =-SUM('P&L'!D12:D14) -> -25735 | F30: =-SUM('P&L'!E12:E14) -> -31716 | G30: =-SUM('P&L'!F12:F14) -> -29760 | H30: =-SUM('P&L'!G12:G14) -> -30578 | I30: =-SUM('P&L'!H12:H14) -> -31665 | J30: =-J29*J13 -> -33591.275 | K30: =-K29*K13 -> -35311.741 | L30: =-L29*L13 -> -37011.81 | M30: =-M29*M13 -> -38686.813 | N30: =-N29*N13 -> -40332.572 | O30: =-O29*O13 -> -41945.395 | P30: =-P29*P13 -> -43522.074 | Q30: =-Q29*Q13 -> -45059.862 | ... S30: =-S29*S13 -> -48009.982
B32: Gross Profit | E32: =SUM(E29:E30) -> 26711 | F32: =SUM(F29:F30) -> 28864 | G32: =SUM(G29:G30) -> 32136 | H32: =SUM(H29:H30) -> 32543 | I32: =SUM(I29:I30) -> 32803 | J32: =SUM(J29:J30) -> 34389.384 | K32: =SUM(K29:K30) -> 36150.727 | L32: =SUM(L29:L30) -> 37891.189 | ... S32: =SUM(S29:S30) -> 49150.671
B34: Expenses
B35: Less: Employee Benefits Expenses | E35: =-'P&L'!D15 -> -2545 | F35: =-'P&L'!E15 -> -2854 | G35: =-'P&L'!F15 -> -3009 | H35: =-'P&L'!G15 -> -3077 | I35: =-'P&L'!H15 -> -3175 | J35: =-J29*J14 -> -3293.6364 | K35: =-K29*K14 -> -3462.3287 | L35: =-L29*L14 -> -3629.0211 | M35: =-M29*M14 -> -3793.2557 | N35: =-N29*N14 -> -3954.6229 | O35: =-O29*O14 -> -4112.7609 | P35: =-P29*P14 -> -4267.3548 | Q35: =-Q29*Q14 -> -4418.1354 | ... S35: =-S29*S14 -> -4707.3957
B36: Less: Other SG&A Expenses | E36: =-'P&L'!D18 -> -11309 | F36: =-'P&L'!E18 -> -11861 | G36: =-'P&L'!F18 -> -14464 | H36: =-'P&L'!G18 -> -14615 | I36: =-'P&L'!H18 -> -14574 | J36: =-J29*J15 -> -14992.582 | K36: =-K29*K15 -> -15760.467 | L36: =-L29*L15 -> -16519.248 | M36: =-M29*M15 -> -17266.842 | N36: =-N29*N15 -> -18001.383 | O36: =-O29*O15 -> -18721.224 | P36: =-P29*P15 -> -19424.933 | Q36: =-Q29*Q15 -> -20111.284 | ... S36: =-S29*S15 -> -21427.993
B38: Earning Before Interest Tax Depeciation & Amortization (EBITDA) | E38: =SUM(E32:E36) -> 12857 | F38: =SUM(F32:F36) -> 14149 | G38: =SUM(G32:G36) -> 14663 | H38: =SUM(H32:H36) -> 14851 | I38: =SUM(I32:I36) -> 15054 | J38: =SUM(J32:J36) -> 16103.166 | K38: =SUM(K32:K36) -> 16927.932 | L38: =SUM(L32:L36) -> 17742.92 | ... S38: =SUM(S32:S36) -> 23015.283
B39: Less: Depreciation & Amortisation Expenses | E39: =-'P&L'!D17 -> -1091 | F39: =-'P&L'!E17 -> -1137 | G39: =-'P&L'!F17 -> -1216 | H39: =-'P&L'!G17 -> -1355 | I39: =-'P&L'!H17 -> -1333 | J39: =J141 -> -1116.9572 | K39: =K141 -> -1025.4913 | L39: =L141 -> -946.13023 | M39: =M141 -> -877.03748 | N39: =N141 -> -816.64298 | O39: =O141 -> -763.60712 | P39: =P141 -> -716.78939 | Q39: =Q141 -> -675.22105 | ... S39: =S141 -> -604.67648
B41: Earning Before Interest Tax (EBIT) | E41: =SUM(E38:E39) -> 11766 | F41: =SUM(F38:F39) -> 13012 | G41: =SUM(G38:G39) -> 13447 | H41: =SUM(H38:H39) -> 13496 | I41: =SUM(I38:I39) -> 13721 | J41: =SUM(J38:J39) -> 14986.208 | K41: =SUM(K38:K39) -> 15902.441 | L41: =SUM(L38:L39) -> 16796.79 | ... S41: =SUM(S38:S39) -> 22410.606
B42: Less: Interest | E42: =-'P&L'!D16 -> -106 | F42: =-'P&L'!E16 -> -114 | G42: =-'P&L'!F16 -> -334 | H42: =-'P&L'!G16 -> -395 | I42: =-'P&L'!H16 -> -410 | J42: =J148 -> -265.52391 | K42: =K148 -> -265.52391 | L42: =L148 -> -265.52391 | M42: =M148 -> -265.52391 | N42: =N148 -> -265.52391 | O42: =O148 -> -265.52391 | P42: =P148 -> -265.52391 | Q42: =Q148 -> -265.52391 | ... S42: =S148 -> -265.52391
B43: Add: Other Income | E43: ='P&L'!D8 -> 258 | F43: ='P&L'!E8 -> 512 | G43: ='P&L'!F8 -> 811 | H43: ='P&L'!G8 -> 1017 | I43: ='P&L'!H8 -> 751 | J43: =J29*J18 -> 737.38221 | K43: =K29*K18 -> 775.14919 | L43: =L29*L18 -> 812.46842 | M43: =M29*M18 -> 849.23742 | N43: =N29*N18 -> 885.36446 | O43: =O29*O18 -> 920.76852 | P43: =P29*P18 -> 955.37914 | Q43: =Q29*Q18 -> 989.13603 | ... S43: =S29*S18 -> 1053.8959
B45: Earning Before Tax & Exceptional Item | E45: =SUM(E41:E43) -> 11918 | F45: =SUM(F41:F43) -> 13410 | G45: =SUM(G41:G43) -> 13924 | H45: =SUM(H41:H43) -> 14118 | I45: =SUM(I41:I43) -> 14062 | J45: =SUM(J41:J43) -> 15458.067 | K45: =SUM(K41:K43) -> 16412.066 | L45: =SUM(L41:L43) -> 17343.734 | ... S45: =SUM(S41:S43) -> 23198.978
B46: Share of loss of equity accounted investee net of tax | E46: ='P&L'!D23 -> 0 | F46: ='P&L'!E23 -> -1 | G46: ='P&L'!F23 -> -4 | H46: ='P&L'!G23 -> -8 | I46: ='P&L'!H23 -> -15 | J46: =I46 -> -15 | K46: =J46 -> -15 | L46: =K46 -> -15 | M46: =L46 -> -15 | N46: =M46 -> -15 | O46: =N46 -> -15 | P46: =O46 -> -15 | Q46: =P46 -> -15 | ... S46: =R46 -> -15
B47: Less: Exceptional Items | E47: ='P&L'!D25 -> -44 | F47: ='P&L'!E25 -> -64 | G47: ='P&L'!F25 -> 6 | H47: ='P&L'!G25 -> 305 | I47: ='P&L'!H25 -> -235 | J47: =I47 -> -235 | K47: =J47 -> -235 | L47: =K47 -> -235 | M47: =L47 -> -235 | N47: =M47 -> -235 | O47: =N47 -> -235 | P47: =O47 -> -235 | Q47: =P47 -> -235 | ... S47: =R47 -> -235
B49: Earning Before Tax | E49: =SUM(E45:E47) -> 11874 | F49: =SUM(F45:F47) -> 13345 | G49: =SUM(G45:G47) -> 13926 | H49: =SUM(H45:H47) -> 14415 | I49: =SUM(I45:I47) -> 13812 | J49: =SUM(J45:J47) -> 15208.067 | K49: =SUM(K45:K47) -> 16162.066 | L49: =SUM(L45:L47) -> 17093.734 | ... S49: =SUM(S45:S47) -> 22948.978
B50: Less: Taxes | E50: =SUM('P&L'!D30:D31,'P&L'!D36) -> -2982 | F50: =SUM('P&L'!E30:E31,'P&L'!E36) -> -3202 | G50: =SUM('P&L'!F30:F31,'P&L'!F36) -> -3644 | H50: =SUM('P&L'!G30:G31,'P&L'!G36) -> -3744 | I50: =SUM('P&L'!H30:H31,'P&L'!H36) -> -3160 | J50: =-J49*J19 -> -3775.4385 | K50: =-K49*K19 -> -4012.271 | L50: =-L49*L19 -> -4243.56 | M50: =-M49*M19 -> -4469.1801 | N50: =-N49*N19 -> -4689.0011 | O50: =-O49*O19 -> -4902.8964 | P50: =-P49*P19 -> -5110.7494 | Q50: =-Q49*Q19 -> -5312.4589 | ... S50: =-S49*S19 -> -5697.1381
B52: Net Earning | E52: =SUM(E49:E50) -> 8892 | F52: =SUM(F49:F50) -> 10143 | G52: =SUM(G49:G50) -> 10282 | H52: =SUM(H49:H50) -> 10671 | I52: =SUM(I49:I50) -> 10652 | J52: =SUM(J49:J50) -> 11432.628 | K52: =SUM(K49:K50) -> 12149.795 | L52: =SUM(L49:L50) -> 12850.174 | ... S52: =SUM(S49:S50) -> 17251.84
B54: PAT | E54: =SUM(E49:E50) -> 8892 | F54: =SUM(F49:F50) -> 10143 | G54: =SUM(G49:G50) -> 10282 | H54: =SUM(H49:H50) -> 10671 | I54: =SUM(I49:I50) -> 10652 | J54: =SUM(J52:J52) -> 11432.628 | K54: =SUM(K52:K52) -> 12149.795 | L54: =SUM(L52:L52) -> 12850.174 | M54: =SUM(M52:M52) -> 13533.388 | N54: =SUM(N52:N52) -> 14199.041 | O54: =SUM(O52:O52) -> 14846.75 | P54: =SUM(P52:P52) -> 15476.162 | Q54: =SUM(Q52:Q52) -> 16086.97 | ... S54: =SUM(S52:S52) -> 17251.84
...

Sheet Ratio
B2: =Model!B2 -> Hindustan Uniliver Ltd
B3: =Model!B3 -> HINDUNILVR | 500696
B4: =Model!B4 -> Financial Statement & DCF Analysis | E4: =Model!E4 -> 2022 | F4: =Model!F4 -> 2023 | G4: =Model!G4 -> 2024 | H4: =Model!H4 -> 2025 | I4: =Model!I4 -> 2026 | J4: =Model!J4 -> 2027 | K4: =Model!K4 -> 2028 | L4: =Model!L4 -> 2029 | ... S4: =Model!S4 -> 2036 | U4: Interpretation
B6: Profitability Ratios
B7: Gross Margin | E7: =Model!E32/Model!E29 -> 0.50930481 | F7: =Model!F32/Model!F29 -> 0.47646088 | G7: =Model!G32/Model!G29 -> 0.51919349 | H7: =Model!H32/Model!H29 -> 0.51556534 | I7: =Model!I32/Model!I29 -> 0.50882608 | J7: =Model!J32/Model!J29 -> 0.50587012 | K7: =Model!K32/Model!K29 -> 0.50587012 | L7: =Model!L32/Model!L29 -> 0.50587012 | ... S7: =Model!S32/Model!S29 -> 0.50587012 | U7: Gross margin fell from 50.9% in 2022 to 47.6% in 2023, then recovered to 51.9% in 2024. It is projected to stabilize at around 50.6% from 2026–2036, indicating stable gross profitability.
B8: EBITDA Margin | E8: =Model!E38/Model!E29 -> 0.24514739 | F8: =Model!F38/Model!F29 -> 0.23355893 | G8: =Model!G38/Model!G29 -> 0.23689738 | H8: =Model!H38/Model!H29 -> 0.23527828 | I8: =Model!I38/Model!I29 -> 0.2335112 | J8: =Model!J38/Model!J29 -> 0.23687863 | K8: =Model!K38/Model!K29 -> 0.23687863 | L8: =Model!L38/Model!L29 -> 0.23687863 | ... S8: =Model!S38/Model!S29 -> 0.23687863 | U8: EBITDA margin declined from 24.5% in 2022 to 23.4% in 2023, then remained stable around 23.7%, indicating consistent operating profitability.
B9: Operating Margin | E9: =Model!E41/Model!E29 -> 0.22434504 | F9: =Model!F41/Model!F29 -> 0.21479036 | G9: =Model!G41/Model!G29 -> 0.21725152 | H9: =Model!H41/Model!H29 -> 0.21381157 | I9: =Model!I41/Model!I29 -> 0.21283427 | J9: =Model!J41/Model!J29 -> 0.22044812 | K9: =Model!K41/Model!K29 -> 0.22252857 | L9: =Model!L41/Model!L29 -> 0.22424723 | ... S9: =Model!S41/Model!S29 -> 0.23065516 | U9: Operating margin fell from 22.4% in 2022 to 21.3% in 2026, but is projected to gradually improve to 22.9% by 2036, indicating improving operating efficiency
B10: Pretax Margin | E10: =Model!E49/Model!E29 -> 0.2264043 | F10: =Model!F49/Model!F29 -> 0.22028722 | G10: =Model!G49/Model!G29 -> 0.22499031 | H10: =Model!H49/Model!H29 -> 0.22837091 | I10: =Model!I49/Model!I29 -> 0.21424583 | J10: =Model!J49/Model!J29 -> 0.22371167 | K10: =Model!K49/Model!K29 -> 0.2261616 | L10: =Model!L49/Model!L29 -> 0.22821162 | ... S10: =Model!S49/Model!S29 -> 0.23619621 | U10: Improved from 22.6% in 2022 to 23.6% by 2036, indicating gradual improvement in profitability before tax.
B11: Effective Tax rate | E11: =-Model!E50/Model!E49 -> 0.25113694 | F11: =-Model!F50/Model!F49 -> 0.23994005 | G11: =-Model!G50/Model!G49 -> 0.26166882 | H11: =-Model!H50/Model!H49 -> 0.25972945 | I11: =-Model!I50/Model!I49 -> 0.22878656 | J11: =-Model!J50/Model!J49 -> 0.24825236 | K11: =-Model!K50/Model!K49 -> 0.24825236 | L11: =-Model!L50/Model!L49 -> 0.24825236 | ... S11: =-Model!S50/Model!S49 -> 0.24825236 | U11: Fluctuated between 22.9%–26.2% historically and is projected to remain stable at 24.8%, indicating a consistent tax burden.
B12: Net Margin | E12: =Model!E54/Model!E29 -> 0.16954582 | F12: =Model!F54/Model!F29 -> 0.1674315 | G12: =Model!G54/Model!G29 -> 0.16611736 | H12: =Model!H54/Model!H29 -> 0.16905626 | I12: =Model!I54/Model!I29 -> 0.16522926 | J12: =Model!J54/Model!J29 -> 0.16817472 | K12: =Model!K54/Model!K29 -> 0.17001644 | L12: =Model!L54/Model!L29 -> 0.17155754 | ... S12: =Model!S54/Model!S29 -> 0.17755994 | U12: Remained around 16.5%–17.0% historically and is projected to gradually increase to 17.7% by 2036, indicating improving overall profitability.
B14: DuPont/Earning Power
B15: Asset Turnover | F15: =Model!F29/AVERAGE(Model!E74:F74) -> 0.84370909 | G15: =Model!G29/AVERAGE(Model!F74:G74) -> 0.81664534 | H15: =Model!H29/AVERAGE(Model!G74:H74) -> 0.797088 | I15: =Model!I29/AVERAGE(Model!H74:I74) -> 0.80770773 | J15: =Model!J29/AVERAGE(Model!I74:J74) -> 0.85563065 | K15: =Model!K29/AVERAGE(Model!J74:K74) -> 0.89548518 | L15: =Model!L29/AVERAGE(Model!K74:L74) -> 0.92329649 | M15: =Model!M29/AVERAGE(Model!L74:M74) -> 0.94924343 | ... S15: =Model!S29/AVERAGE(Model!R74:S74) -> 1.0663175 | U15: Asset turnover is projected to improve from 0.8x to 1.3x, indicating that the company is expected to use its assets more efficiently to generate revenue over the forecast period.
B17: Liquidity Ratio
B18: Quick ratio | E18: =SUM(Model!E60:E62)/SUM(Model!E78:E79) -> 0.55401713 | F18: =SUM(Model!F60:F62)/SUM(Model!F78:F79) -> 0.66778581 | G18: =SUM(Model!G60:G62)/SUM(Model!G78:G79) -> 0.84461514 | H18: =SUM(Model!H60:H62)/SUM(Model!H78:H79) -> 0.70499628 | I18: =SUM(Model!I60:I62)/SUM(Model!I78:I79) -> 0.43670511 | J18: =SUM(Model!J60:J62)/SUM(Model!J78:J79) -> 0.47539133 | K18: =SUM(Model!K60:K62)/SUM(Model!K78:K79) -> 0.56784092 | L18: =SUM(Model!L60:L62)/SUM(Model!L78:L79) -> 0.65042867 | ... S18: =SUM(Model!S60:S62)/SUM(Model!S78:S79) -> 1.075639 | U18: Declined to 0.4x in 2026 but is projected to improve to 0.9x by 2036, indicating strengthening short-term liquidity.
B19: Current ratio | E19: =SUM(Model!E60:E64)/SUM(Model!E78:E79) -> 1.0901804 | F19: =SUM(Model!F60:F64)/SUM(Model!F78:F79) -> 1.2182335 | G19: =SUM(Model!G60:G64)/SUM(Model!G78:G79) -> 1.3384542 | H19: =SUM(Model!H60:H64)/SUM(Model!H78:H79) -> 1.1315398 | I19: =SUM(Model!I60:I64)/SUM(Model!I78:I79) -> 0.97028007 | J19: =SUM(Model!J60:J64)/SUM(Model!J78:J79) -> 1.0622099 | K19: =SUM(Model!K60:K64)/SUM(Model!K78:K79) -> 1.1468332 | L19: =SUM(Model!L60:L64)/SUM(Model!L78:L79) -> 1.222315 | ... S19: =SUM(Model!S60:S64)/SUM(Model!S78:S79) -> 1.6125365 | U19: Fell to 1.0x in 2026 and is projected to rise to 1.4x by 2036, indicating improved ability to meet short-term obligations.
B20: Cash Cycle (Days) | E20: =Model!E21+Model!E22-Model!E23 -> -54.956442 | F20: =Model!F21+Model!F22-Model!F23 -> -42.707889 | G20: =Model!G21+Model!G22-Model!G23 -> -61.606295 | H20: =Model!H21+Model!H22-Model!H23 -> -60.279599 | I20: =Model!I21+Model!I22-Model!I23 -> -79.262846 | J20: =Model!J21+Model!J22-Model!J23 -> -59.762614 | K20: =Model!K21+Model!K22-Model!K23 -> -59.762614 | L20: =Model!L21+Model!L22-Model!L23 -> -59.762614 | ... S20: =Model!S21+Model!S22-Model!S23 -> -59.762614 | U20: Remains negative at around -59.8 days throughout the forecast period, indicating the company receives cash from operations before paying its suppliers.
B22: Leverage
B23: Asset/Equity | E23: =Model!E74/Model!E90 -> 1.4373331 | F23: =Model!F74/Model!F90 -> 1.4529063 | G23: =Model!G74/Model!G90 -> 1.5326448 | H23: =Model!H74/Model!H90 -> 1.6169386 | I23: =Model!I74/Model!I90 -> 1.6363077 | J23: =Model!J74/Model!J90 -> 1.6026688 | K23: =Model!K74/Model!K90 -> 1.6067409 | L23: =Model!L74/Model!L90 -> 1.6100815 | ... S23: =Model!S74/Model!S90 -> 1.6139578 | U23: Increased from 1.44x to 1.68x, indicating a gradual increase in asset utilization relative to shareholders’ equity.
B24: Debt/Equity | E24: =Model!E82/Model!E90 -> 0.021259249 | F24: =Model!F82/Model!F90 -> 0.024232665 | G24: =Model!G82/Model!G90 -> 0.028974189 | H24: =Model!H82/Model!H90 -> 0.033358973 | I24: =Model!I82/Model!I90 -> 0.030324791 | J24: =Model!J82/Model!J90 -> 0.029927329 | K24: =Model!K82/Model!K90 -> 0.029516198 | L24: =Model!L82/Model!L90 -> 0.029093482 | ... S24: =Model!S82/Model!S90 -> 0.025965954 | U24: Remains very low at around 0.03x, indicating low financial leverage and limited reliance on debt financing.
B26: Operating
B27: A/R Turnover | F27: =Model!F29/AVERAGE(Model!E62:F62) -> 22.795861 | G27: =Model!G29/AVERAGE(Model!F62:G62) -> 20.37393 | H27: =Model!H29/AVERAGE(Model!G62:H62) -> 18.52142 | I27: =Model!I29/AVERAGE(Model!H62:I62) -> 17.912754 | J27: =Model!J29/AVERAGE(Model!I62:J62) -> 19.867972 | K27: =Model!K29/AVERAGE(Model!J62:K62) -> 20.113525 | L27: =Model!L29/AVERAGE(Model!K62:L62) -> 20.084817 | M27: =Model!M29/AVERAGE(Model!L62:M62) -> 20.057753 | ... S27: =Model!S29/AVERAGE(Model!R62:S62) -> 19.925159 | U27: Declines initially but stabilizes around 20.3x, indicating consistent collection efficiency.
B28: Avg. A/R Days | F28: =Model!F21 -> 18.551255 | G28: =Model!G21 -> 17.673275 | H28: =Model!H21 -> 22.083538 | I28: =Model!I21 -> 19.130964 | J28: =Model!J21 -> 18.600112 | K28: =Model!K21 -> 18.600112 | L28: =Model!L21 -> 18.600112 | M28: =Model!M21 -> 18.600112 | ... S28: =Model!S21 -> 18.600112 | U28: Remains stable at around 19 days, indicating efficient receivables collection.
B29: Inventory Turnover | F29: =-Model!F30/AVERAGE(Model!E63:F63) -> 7.599377 | G29: =-Model!G30/AVERAGE(Model!F63:G63) -> 7.1944881 | H29: =-Model!H30/AVERAGE(Model!G63:H63) -> 7.2485481 | I29: =-Model!I30/AVERAGE(Model!H63:I63) -> 6.880704 | J29: =-Model!J30/AVERAGE(Model!I63:J63) -> 6.9599103 | K29: =-Model!K30/AVERAGE(Model!J63:K63) -> 7.0788482 | L29: =-Model!L30/AVERAGE(Model!K63:L63) -> 7.0687445 | M29: =-Model!M30/AVERAGE(Model!L63:M63) -> 7.0592194 | ... S29: =-Model!S30/AVERAGE(Model!R63:S63) -> 7.0125538 | U29: Remains around 7.1x, indicating stable inventory management.
B30: Avg. Inventory Days | F30: =Model!F22 -> 48.922153 | G30: =Model!G22 -> 49.328965 | H30: =Model!H22 -> 52.700471 | I30: =Model!I22 -> 55.202432 | J30: =Model!J22 -> 52.849533 | K30: =Model!K22 -> 52.849533 | L30: =Model!L22 -> 52.849533 | M30: =Model!M22 -> 52.849533 | ... S30: =Model!S22 -> 52.849533 | U30: Stabilizes at around 53 days, showing consistent inventory holding.
B31: A/P Turnover | F31: =-Model!F30/AVERAGE(Model!E78:F78) -> 3.4026392 | G31: =-Model!G30/AVERAGE(Model!F78:G78) -> 2.9670987 | H31: =-Model!H30/AVERAGE(Model!G78:H78) -> 2.8051924 | I31: =-Model!I30/AVERAGE(Model!H78:I78) -> 2.570211 | J31: =-Model!J30/AVERAGE(Model!I78:J78) -> 2.6449218 | K31: =-Model!K30/AVERAGE(Model!J78:K78) -> 2.8512109 | L31: =-Model!L30/AVERAGE(Model!K78:L78) -> 2.8471413 | M31: =-Model!M30/AVERAGE(Model!L78:M78) -> 2.8433048 | ... S31: =-Model!S30/AVERAGE(Model!R78:S78) -> 2.8245089 | U31: A/P turnover declined from 3.4x to 2.6x, then stabilized at around 2.9x, indicating a consistent supplier payment pattern during the forecast period.
B32: Avg. A/P Days | F32: =Model!F23 -> 110.1813 | G32: =Model!G23 -> 128.60853 | H32: =Model!H23 -> 135.06361 | I32: =Model!I23 -> 153.59624 | J32: =Model!J23 -> 131.21226 | K32: =Model!K23 -> 131.21226 | L32: =Model!L23 -> 131.21226 | M32: =Model!M23 -> 131.21226 | ... S32: =Model!S23 -> 131.21226 | U32: A/P Days remain around 131 days, indicating extended supplier payment periods
B33: Fixed Asset Turnover | F33: =Model!F29/AVERAGE(Model!E67:F67) -> 9.236164 | G33: =Model!G29/AVERAGE(Model!F67:G67) -> 8.2638184 | H33: =Model!H29/AVERAGE(Model!G67:H67) -> 7.5793708 | I33: =Model!I29/AVERAGE(Model!H67:I67) -> 7.6715654 | J33: =Model!J29/AVERAGE(Model!I67:J67) -> 8.6632735 | K33: =Model!K29/AVERAGE(Model!J67:K67) -> 9.8960414 | L33: =Model!L29/AVERAGE(Model!K67:L67) -> 11.217075 | M33: =Model!M29/AVERAGE(Model!L67:M67) -> 12.621106 | ... S33: =Model!S29/AVERAGE(Model!R67:S67) -> 22.498176 | U33: Improves from 8.7x to 16.8x, indicating significantly better utilization of fixed assets.
B34: ROIC | F34: =Model!F41*(1-Model!F19)/AVERAGE((Model!E90+Model!E82-Model!E60),(Model!F90+Model!F82-Model!F60)) -> 0.19826193 | G34: =Model!G41*(1-Model!G19)/AVERAGE((Model!F90+Model!F82-Model!F60),(Model!G90+Model!G82-Model!G60)) -> 0.19337279 | H34: =Model!H41*(1-Model!H19)/AVERAGE((Model!G90+Model!G82-Model!G60),(Model!H90+Model!H82-Model!H60)) -> 0.2062999 | I34: =Model!I41*(1-Model!I19)/AVERAGE((Model!H90+Model!H82-Model!H60),(Model!I90+Model!I82-Model!I60)) -> 0.22851694 | J34: =Model!J41*(1-Model!J19)/AVERAGE((Model!I90+Model!I82-Model!I60),(Model!J90+Model!J82-Model!J60)) -> 0.23468696 | K34: =Model!K41*(1-Model!K19)/AVERAGE((Model!J90+Model!J82-Model!J60),(Model!K90+Model!K82-Model!K60)) -> 0.24912315 | L34: =Model!L41*(1-Model!L19)/AVERAGE((Model!K90+Model!K82-Model!K60),(Model!L90+Model!L82-Model!L60)) -> 0.26722417 | M34: =Model!M41*(1-Model!M19)/AVERAGE((Model!L90+Model!L82-Model!L60),(Model!M90+Model!M82-Model!M60)) -> 0.28509543 | ... S34: =Model!S41*(1-Model!S19)/AVERAGE((Model!R90+Model!R82-Model!R60),(Model!S90+Model!S82-Model!S60)) -> 0.38593683 | U34: Increases from 24% to 46%, indicating strong improvement in returns generated on invested capital.

Sheet WACC
B2: =Model!B2 -> Hindustan Uniliver Ltd
B3: =Model!B3 -> HINDUNILVR | 500696
B4: =Model!B4 -> Financial Statement & DCF Analysis
B6: Comparable Company Beta
B8: Company Name | D8: Equity Value | E8: Total Debt | F8: Debt/Equity | G8: Debt/Capital | H8: Tax Rate | I8: Levered Beta | J8: Unlevered Beta
B10: ='Comparables Analysis'!B9 -> Hind. Unilever | D10: ='Comparables Analysis'!F9 -> 453941.03 | E10: ='Comparables Analysis'!G9 -> 1478 | F10: =E10/D10 -> 0.0032559295 | G10: =E10/(D10+E10) -> 0.0032453628 | H10: ='Company Data'!S8 -> 0.25 | I10: 0.32 | J10: =I10/(1+F10*(1-H10)) -> 0.31922048
B11: ='Comparables Analysis'!B10 -> ITC | D11: ='Comparables Analysis'!F10 -> 328675.46 | E11: ='Comparables Analysis'!G10 -> 2399.06 | F11: =E11/D11 -> 0.0072991759 | G11: =E11/(D11+E11) -> 0.007246284 | H11: ='Company Data'!S9 -> 0.25 | I11: -0.24 | J11: =I11/(1+F11*(1-H11)) -> -0.2386933
B12: ='Comparables Analysis'!B11 -> Hindustan Foods | D12: ='Comparables Analysis'!F11 -> 7581.15 | E12: ='Comparables Analysis'!G11 -> 1088.26 | F12: =E12/D12 -> 0.14354814 | G12: =E12/(D12+E12) -> 0.12552873 | H12: ='Company Data'!S10 -> 0.25 | I12: 0.33 | J12: =I12/(1+F12*(1-H12)) -> 0.29792506
B13: ='Comparables Analysis'!B12 -> Godavari Bioref. | D13: ='Comparables Analysis'!F12 -> 1233.39 | E13: ='Comparables Analysis'!G12 -> 530.76 | F13: =E13/D13 -> 0.43032617 | G13: =E13/(D13+E13) -> 0.30085877 | H13: ='Company Data'!S11 -> 0.23 | I13: 0.13 | J13: =I13/(1+F13*(1-H13)) -> 0.097645163
B15: Average | F15: =AVERAGE(F7:F13) -> 0.14610736 | G15: =AVERAGE(G7:G13) -> 0.10921979 | H15: =AVERAGE(H7:H13) -> 0.245 | I15: =AVERAGE(I7:I13) -> 0.135 | J15: =AVERAGE(J7:J13) -> 0.11902435
B16: Median | F16: =MEDIAN(F7:F13) -> 0.075423659 | G16: =MEDIAN(G7:G13) -> 0.066387505 | H16: =MEDIAN(H7:H13) -> 0.25 | I16: =MEDIAN(I7:I13) -> 0.225 | J16: =MEDIAN(J7:J13) -> 0.19778511
B18: =B10 -> Hind. Unilever | D18: =D10 -> 453941.03 | E18: =E10 -> 1478 | F18: =F10 -> 0.0032559295 | G18: =G10 -> 0.0032453628 | H18: =H10 -> 0.25 | I18: =I10 -> 0.32 | J18: =J10 -> 0.31922048
B20: WACC Calculation
B22: Target Capital Structure
B24: Proportion of Debt | D24: =G15 -> 0.10921979
B25: Proportion of Equity | D25: =1-D24 -> 0.89078021
B27: Current Capital Structure
B29: Market Cap | D29: =D18 -> 453941.03
B30: Total Debt | D30: =E18 -> 1478
B31: Debt/Equity | D31: =D30/D29 -> 0.0032559295
B33: Cost of Debt
B35: Pre-Tax Cost of Debt | D35: 0.08
B36: Tax Rate | D36: =Model!J19 -> 0.24825236
B37: After Tax Cost of Debt | D37: =D35*(1-D36) -> 0.060139811
B39: Cost of Equity
B41: Risk Free Rate (Rf) | D41: 0.0676
B42: Equity Market Return | D42: ='Index Data'!F10 -> 0.10036107
B43: Equity Risk Premium (ERP) | D43: =D42-D41 -> 0.032761074
B44: Levered Market Beta | D44: =J16*(1+D31*(1-D36)) -> 0.19826922
B45: Cost of Equity | D45: =D41+(D43*D44) -> 0.074095512
B47: WACC | D47: =(D37*D24)+(D45*D25) -> 0.072571274

Sheet Beta
B2: =Model!B2 -> Hindustan Uniliver Ltd
B3: =Model!B3 -> HINDUNILVR | 500696
B4: =Model!B4 -> Financial Statement & DCF Analysis
C6: Index | D6: % Change | E6: Stock | F6: % Change | H6: 52W High | I6: =MAX(E48:E59) -> 2467
B7: Date | C7: Close Price | D7: Monthly | E7: Close Price | F7: Monthly | H7: 52W Low | I7: =MIN(E48:E59) -> 1934.95
B9: 44743 | C9: 57570.25 | E9: 2636.85 | H9: Beta | I9: =SLOPE(D10:D59,F10:F59) -> 0.33326978
B10: 44774 | C10: 59537.07 | D10: =C10/C9-1 -> 0.034163826 | E10: 2659 | F10: =E10/E9-1 -> 0.0084001745
B11: 44805 | C11: 57426.92 | D11: =C11/C10-1 -> -0.035442624 | E11: 2696.85 | F11: =E11/E10-1 -> 0.014234675
B12: 44835 | C12: 60746.59 | D12: =C12/C11-1 -> 0.057806861 | E12: 2548.05 | F12: =E12/E11-1 -> -0.055175483 | H12: SUMMARY OUTPUT
B13: 44866 | C13: 63099.65 | D13: =C13/C12-1 -> 0.038735672 | E13: 2680.15 | F13: =E13/E12-1 -> 0.051843567
B14: 44896 | C14: 60840.74 | D14: =C14/C13-1 -> -0.035799089 | E14: 2559.75 | F14: =E14/E13-1 -> -0.044922859 | H14: Regression Statistics
B15: 44927 | C15: 59549.9 | D15: =C15/C14-1 -> -0.021216704 | E15: 2577.6 | F15: =E15/E14-1 -> 0.0069733372 | H15: Multiple R | I15: 0.49138587
B16: 44958 | C16: 58962.12 | D16: =C16/C15-1 -> -0.0098703776 | E16: 2457.65 | F16: =E16/E15-1 -> -0.046535537 | H16: R Square | I16: 0.24146007
B17: 44986 | C17: 58991.52 | D17: =C17/C16-1 -> 0.00049862522 | E17: 2558.75 | F17: =E17/E16-1 -> 0.041136858 | H17: Adjusted R Square | I17: 0.22565715
B18: 45017 | C18: 61112.44 | D18: =C18/C17-1 -> 0.035952964 | E18: 2454.4 | F18: =E18/E17-1 -> -0.040781632 | H18: Standard Error | I18: 0.032978299
B19: 45047 | C19: 62622.24 | D19: =C19/C18-1 -> 0.024705281 | E19: 2660.75 | F19: =E19/E18-1 -> 0.084073501 | H19: Observations | I19: 50
B20: 45078 | C20: 64718.56 | D20: =C20/C19-1 -> 0.033475647 | E20: 2678.4 | F20: =E20/E19-1 -> 0.006633468
B21: 45108 | C21: 66527.67 | D21: =C21/C20-1 -> 0.027953496 | E21: 2561.5 | F21: =E21/E20-1 -> -0.04364546 | H21: ANOVA
B22: 45139 | C22: 64831.41 | D22: =C22/C21-1 -> -0.02549706 | E22: 2504.2 | F22: =E22/E21-1 -> -0.022369705 | I22: df | J22: SS | K22: MS | L22: F | M22: Significance F
B23: 45170 | C23: 65828.41 | D23: =C23/C22-1 -> 0.015378348 | E23: 2465.85 | F23: =E23/E22-1 -> -0.015314272 | H23: Regression | I23: 1 | J23: 0.016617458 | K23: 0.016617458 | L23: 15.279464 | M23: 0.00029045002
B24: 45200 | C24: 63874.93 | D24: =C24/C23-1 -> -0.029675333 | E24: 2484 | F24: =E24/E23-1 -> 0.007360545 | H24: Residual | I24: 48 | J24: 0.052203272 | K24: 0.0010875682
B25: 45231 | C25: 66988.44 | D25: =C25/C24-1 -> 0.04874385 | E25: 2546.7 | F25: =E25/E24-1 -> 0.025241546 | H25: Total | I25: 49 | J25: 0.068820731
B26: 45261 | C26: 72240.26 | D26: =C26/C25-1 -> 0.0783989 | E26: 2663.35 | F26: =E26/E25-1 -> 0.045804374
B27: 45292 | C27: 71752.11 | D27: =C27/C26-1 -> -0.0067573123 | E27: 2480.4 | F27: =E27/E26-1 -> -0.068691685 | I27: Coefficients | J27: Standard Error | K27: t Stat | L27: P-value | M27: Lower 95% | N27: Upper 95% | O27: Lower 95.0% | P27: Upper 95.0%
B28: 45323 | C28: 72500.3 | D28: =C28/C27-1 -> 0.010427429 | E28: 2411.05 | F28: =E28/E27-1 -> -0.0279592 | H28: Intercept | I28: 0.0073588738 | J28: 0.0046806654 | K28: 1.5721854 | L28: 0.12247673 | M28: -0.0020522347 | N28: 0.016769982 | O28: -0.0020522347 | P28: 0.016769982
B29: 45352 | C29: 73651.35 | D29: =C29/C28-1 -> 0.015876486 | E29: 2268.25 | F29: =E29/E28-1 -> -0.059227308 | H29: X Variable 1 | I29: 0.33326978 | J29: 0.085259323 | K29: 3.9088955 | L29: 0.00029045002 | M29: 0.16184442 | N29: 0.50469514 | O29: 0.16184442 | P29: 0.50469514
B30: 45383 | C30: 74482.78 | D30: =C30/C29-1 -> 0.011288727 | E30: 2230.7 | F30: =E30/E29-1 -> -0.016554613
B31: 45413 | C31: 73961.31 | D31: =C31/C30-1 -> -0.0070012156 | E31: 2328.7 | F31: =E31/E30-1 -> 0.043932398
B32: 45444 | C32: 79032.73 | D32: =C32/C31-1 -> 0.068568553 | E32: 2475.2 | F32: =E32/E31-1 -> 0.062910637
B33: 45474 | C33: 81741.34 | D33: =C33/C32-1 -> 0.034272004 | E33: 2706.05 | F33: =E33/E32-1 -> 0.093265191
B34: 45505 | C34: 82365.77 | D34: =C34/C33-1 -> 0.0076390967 | E34: 2778.1 | F34: =E34/E33-1 -> 0.026625524
B35: 45536 | C35: 84299.78 | D35: =C35/C34-1 -> 0.023480749 | E35: 2959.4 | F35: =E35/E34-1 -> 0.06526043
B36: 45566 | C36: 79389.06 | D36: =C36/C35-1 -> -0.058253058 | E36: 2527.5 | F36: =E36/E35-1 -> -0.14594174
B37: 45597 | C37: 79802.79 | D37: =C37/C36-1 -> 0.0052114233 | E37: 2496.25 | F37: =E37/E36-1 -> -0.012363996
B38: 45627 | C38: 78139.01 | D38: =C38/C37-1 -> -0.020848645 | E38: 2326.75 | F38: =E38/E37-1 -> -0.067901853
B39: 45658 | C39: 77500.57 | D39: =C39/C38-1 -> -0.0081705668 | E39: 2471.3 | F39: =E39/E38-1 -> 0.062125282
B40: 45689 | C40: 73198.1 | D40: =C40/C39-1 -> -0.055515334 | E40: 2191.8 | F40: =E40/E39-1 -> -0.11309837
B41: 45717 | C41: 77414.92 | D41: =C41/C40-1 -> 0.057608326 | E41: 2259.35 | F41: =E41/E40-1 -> 0.030819418
... B59: 46266 | C59: 74294.96 | D59: =C59/C58-1 -> -0.053557382 | E59: 1934.95 | F59: =E59/E58-1 -> -0.030100251

Sheet Comparables Analysis
B2: =Model!B2 -> Hindustan Uniliver Ltd
B3: =Model!B3 -> HINDUNILVR | 500696
B4: =Model!B4 -> Financial Statement & DCF Analysis
D6: Market Data | K6: Financial Data | O6: Valuations
B7: Company Name | C7: All No.s In Cr. | D7: Price (Rs) | E7: Shares (MM.) | F7: Market Cap. | G7: Debt | H7: Cash & Equivalent | I7: EV | K7: Sales | L7: EBITDA | M7: Earning | O7: EV/Sales | P7: EV/EBITDA | Q7: P/E
B9: Hind. Unilever | D9: ='Company Data'!D8 -> 1932 | E9: ='Company Data'!F8 -> 234.95913 | F9: =D9*E9 -> 453941.03 | G9: ='Company Data'!G8 -> 1478 | H9: ='Company Data'!N8 -> 3248 | I9: =F9+G9-H9 -> 452171.03 | K9: ='Company Data'!I8 -> 66052 | L9: ='Company Data'!J8 -> 15039 | M9: ='Company Data'!M8 -> 11027.55 | O9: =I9/K9 -> 6.8456826 | P9: =I9/L9 -> 30.066562 | Q9: ='Company Data'!L8 -> 41.16
B10: ITC | D10: ='Company Data'!D9 -> 262.3 | E10: ='Company Data'!F9 -> 1253.0517 | F10: =D10*E10 -> 328675.46 | G10: ='Company Data'!G9 -> 2399.06 | H10: ='Company Data'!N9 -> 3008.79 | I10: =F10+G10-H10 -> 328065.73 | K10: ='Company Data'!I9 -> 76487.98 | L10: ='Company Data'!J9 -> 27306 | M10: ='Company Data'!M9 -> 19748.27 | O10: =I10/K10 -> 4.2891148 | P10: =I10/L10 -> 12.014419 | Q10: ='Company Data'!L9 -> 16.64
B11: Hindustan Foods | D11: ='Company Data'!D10 -> 625.7 | E11: ='Company Data'!F10 -> 12.11627 | F11: =D11*E11 -> 7581.15 | G11: ='Company Data'!G10 -> 1088.26 | H11: ='Company Data'!N10 -> 51.71 | I11: =F11+G11-H11 -> 8617.7 | K11: ='Company Data'!I10 -> 4400.19 | L11: ='Company Data'!J10 -> 363 | M11: ='Company Data'!M10 -> 161.76 | O11: =I11/K11 -> 1.9584836 | P11: =I11/L11 -> 23.74022 | Q11: ='Company Data'!L10 -> 46.87
B12: Godavari Bioref. | D12: ='Company Data'!D11 -> 241.01 | E12: ='Company Data'!F11 -> 5.1175885 | F12: =D12*E12 -> 1233.39 | G12: ='Company Data'!G11 -> 530.76 | H12: ='Company Data'!N11 -> 32.15 | I12: =F12+G12-H12 -> 1732 | K12: ='Company Data'!I11 -> 2012.58 | L12: ='Company Data'!J11 -> 127 | M12: ='Company Data'!M11 -> 29.01 | O12: =I12/K12 -> 0.86058691 | P12: =I12/L12 -> 13.637795 | Q12: ='Company Data'!L11 -> 42.52
B14: Average | O14: =AVERAGE(O9:O12) -> 3.488467 | P14: =AVERAGE(P9:P12) -> 19.864749 | Q14: =AVERAGE(Q9:Q12) -> 36.7975
B15: Median | O15: =MEDIAN(O9:O12) -> 3.1237992 | P15: =MEDIAN(P9:P12) -> 18.689008 | Q15: =MEDIAN(Q9:Q12) -> 41.84
B17: =B9 -> Hind. Unilever | D17: =D9 -> 1932 | E17: =E9 -> 234.95913 | F17: =F9 -> 453941.03 | G17: =G9 -> 1478 | H17: =H9 -> 3248 | I17: =I9 -> 452171.03 | K17: =K9 -> 66052 | L17: =L9 -> 15039 | M17: =M9 -> 11027.55 | O17: =O9 -> 6.8456826 | P17: =P9 -> 30.066562 | Q17: =Q9 -> 41.16
B19: Metric | D19: Comps | E19: EV | F19: Net Debt | G19: Equity Value | H19: Shares | I19: Share Price
B21: EV/Sales | D21: =O14 -> 3.488467 | E21: =D21*K17 -> 230420.22 | F21: =$G$17-$H$17 -> -1770 | G21: =E21+F21 -> 228650.22 | H21: =E17 -> 234.95913 | I21: =G21/H21 -> 973.14893
B22: EV/EBITDA | D22: =P15 -> 18.689008 | E22: =D22*L17 -> 281063.99 | F22: =$G$17-$H$17 -> -1770 | G22: =E22+F22 -> 279293.99 | H22: =H21 -> 234.95913 | I22: =G22/H22 -> 1188.6918
B23: P/E | D23: =Q14 -> 36.7975 | E23: =G23+F23 -> 404016.27 | F23: =$G$17-$H$17 -> -1770 | G23: =D23*M17 -> 405786.27 | H23: =H22 -> 234.95913 | I23: =G23/H23 -> 1727.0505

Sheet Index Data
B2: =Model!B2 -> Hindustan Uniliver Ltd
B3: =Model!B3 -> HINDUNILVR | 500696
B4: =Model!B4 -> Financial Statement & DCF Analysis
C6: Index | E6: Nifty 50 Tri
B7: Date | C7: Close Price
E8: Years | F8: =YEARFRAC(B9,B2495) -> 10.033333
B9: 46283 | C9: 23346.4
B10: 46282 | C10: 23270.6 | E10: Market Return | F10: =_xlfn.RRI(F8,C2495,C9) -> 0.10036107
B11: 46281 | C11: 23217.6
B12: 46280 | C12: 23118.6
B13: 46276 | C13: 23398.1
B14: 46275 | C14: 23477.8
B15: 46274 | C15: 23431.5
B16: 46273 | C16: 23635.1
B17: 46272 | C17: 23779.15
B18: 46269 | C18: 23897.7
B19: 46268 | C19: 23873.45
B20: 46267 | C20: 23914.45
B21: 46266 | C21: 24055.8
B22: 46265 | C22: 24080.4
... B2514: 42590 | C2514: 8711.35

Sheet Scenario
B2: =Model!B2 -> Hindustan Uniliver Ltd
B3: =Model!B3 -> HINDUNILVR | 500696
B4: =Model!B4 -> Financial Statement & DCF Analysis
B6: Scenarios | D6: Growth (%) | E6: =Model!J4 -> 2027 | F6: =Model!K4 -> 2028 | G6: =Model!L4 -> 2029 | H6: =Model!M4 -> 2030 | I6: =Model!N4 -> 2031 | J6: =Model!O4 -> 2032 | K6: =Model!P4 -> 2033 | L6: =Model!Q4 -> 2034 | ... N6: =Model!S4 -> 2036
B8: Base Case | D8: =AVERAGE(Model!F12:I12) -> 0.054486857 | E8: =D8 -> 0.054486857 | F8: =E8*(1-$D$11) -> 0.051217645 | G8: =F8*(1-$D$11) -> 0.048144587 | H8: =G8*(1-$D$11) -> 0.045255911 | I8: =H8*(1-$D$11) -> 0.042540557 | J8: =I8*(1-$D$11) -> 0.039988123 | K8: =J8*(1-$D$11) -> 0.037588836 | L8: =K8*(1-$D$11) -> 0.035333506 | M8: =L8*(1-$D$11) -> 0.033213495 | N8: =M8*(1-$D$11) -> 0.031220686
B9: Bull Case | D9: =MAX(Model!E12:I12) -> 0.15509286 | E9: =D9 -> 0.15509286 | F9: =E9*(1-$D$11) -> 0.14578729 | G9: =F9*(1-$D$11) -> 0.13704005 | H9: =G9*(1-$D$11) -> 0.12881765 | I9: =H9*(1-$D$11) -> 0.12108859 | J9: =I9*(1-$D$11) -> 0.11382327 | K9: =J9*(1-$D$11) -> 0.10699388 | L9: =K9*(1-$D$11) -> 0.10057424 | M9: =L9*(1-$D$11) -> 0.094539788 | N9: =M9*(1-$D$11) -> 0.088867401
B10: Bear Case | D10: =MIN(Model!F12:I12) -> 0.019791263 | E10: =D10 -> 0.019791263 | F10: =E10*(1-$D$11) -> 0.018603787 | G10: =F10*(1-$D$11) -> 0.01748756 | H10: =G10*(1-$D$11) -> 0.016438306 | I10: =H10*(1-$D$11) -> 0.015452008 | J10: =I10*(1-$D$11) -> 0.014524887 | K10: =J10*(1-$D$11) -> 0.013653394 | L10: =K10*(1-$D$11) -> 0.01283419 | M10: =L10*(1-$D$11) -> 0.012064139 | N10: =M10*(1-$D$11) -> 0.011340291
B11: Annual Growth Tapering | D11: 0.06

Sheet BS
B2: HUL
B4: Particular | D4: 2022 | E4: =D4+1 -> 2023 | F4: =E4+1 -> 2024 | G4: =F4+1 -> 2025 | H4: =G4+1 -> 2026
B5: All Values In Crores
B7: ASSETS
B8: Non-current assets
B9: Property, plant and equipment | D9: 6169 | E9: 6949 | F9: 8031 | G9: 8625 | H9: 8182
B10: Capital work-in-progress | D10: 1313 | E10: 1132 | F10: 1025 | G10: 1009 | H10: 880
B11: Goodwill | D11: =17316+81 -> 17397 | E11: =17316+150 -> 17466 | F11: 17466 | G11: 17466 | H11: 18062
B12: Other intangible assets | D12: 27907 | E12: 28263 | F12: 28247 | G12: 28244 | H12: 31184
B13: Investments accounted for using the equity method | D13: 0 | E13: 69 | F13: 65 | G13: 57 | H13: 0
B14: Financial assets
B15: Investments | D15: 2 | E15: 2 | F15: 2 | G15: 2 | H15: 112
B16: Loans | D16: 115 | E16: 98 | F16: 102 | G16: 87 | H16: 85
B17: Other financial assets | D17: 729 | E17: 725 | F17: 760 | G17: 763 | H17: 709
B18: Deferred tax assets | D18: 11 | E18: 10 | F18: 10 | G18: 17 | H18: 14
B19: Non-current tax assets (net) | D19: 1158 | E19: 1164 | F19: 1175 | G19: 1199 | H19: 1146
B20: Other non-current assets | D20: 194 | E20: 211 | F20: 292 | G20: 360 | H20: 357
B21: Total – Non-current assets (A) | D21: =SUM(D9:D20) -> 54995 | E21: =SUM(E9:E20) -> 56089 | F21: =SUM(F9:F20) -> 57175 | G21: =SUM(G9:G20) -> 57829 | H21: =SUM(H9:H20) -> 60731
B23: Current assets
B24: Inventories | D24: 4096 | E24: 4251 | F24: 4022 | G24: 4415 | H24: 4789
B25: Financial assets
B26: Investments | D26: 3519 | E26: 2811 | F26: 4558 | G26: 3751 | H26: 4247
B27: Trade receivables | D27: 2236 | E27: 3079 | F27: 2997 | G27: 3819 | H27: 3379
B28: Cash and cash equivalents | D28: 1147 | E28: 714 | F28: 825 | G28: 6071 | H28: 2583
B29: Bank balances other than cash and cash equivalents mentioned above | D29: 2699 | E29: 3964 | F29: 6734 | G29: 1483 | H29: 665
B30: Loans | D30: 35 | E30: 36 | F30: 38 | G30: 46 | H30: 50
B31: Other financial assets | D31: 1089 | E31: 1386 | F31: 1425 | G31: 1488 | H31: 1979
B32: Current tax assets (net) | D32: 0 | E32: 0 | F32: 0 | G32: 0 | H32: 156
B33: Other current assets | D33: 688 | E33: 745 | F33: 713 | G33: 955 | H33: 1159
B34: Assets held for sale | D34: 13 | E34: 12 | F34: 12 | G34: 23 | H34: 14
B35: Total – Current assets (B) | D35: =SUM(D24:D34) -> 15522 | E35: =SUM(E24:E34) -> 16998 | F35: =SUM(F24:F34) -> 21324 | G35: =SUM(G24:G34) -> 22051 | H35: =SUM(H24:H34) -> 19021
B37: TOTAL ASSETS (A+B) | D37: =D21+D35 -> 70517 | E37: =E21+E35 -> 73087 | F37: =F21+F35 -> 78499 | G37: =G21+G35 -> 79880 | H37: =H21+H35 -> 79752
B39: EQUITY AND LIABILITIES
B40: Equity
B41: Equity share capital | D41: 235 | E41: 235 | F41: 235 | G41: 235 | H41: 235
B42: Other equity | D42: 48826 | E42: 50069 | F42: 50983 | G42: 49167 | H42: 48504
B43: Non-controlling interests | D43: 26 | E43: 218 | F43: 205 | G43: 207 | H43: 269
B44: Total – Equity (A) | D44: =SUM(D41:D43) -> 49087 | E44: =SUM(E41:E43) -> 50522 | F44: =SUM(F41:F43) -> 51423 | G44: =SUM(G41:G43) -> 49609 | H44: =SUM(H41:H43) -> 49008
B46: Liabilities
B47: Non-current liabilities
...

Sheet P&L
B3: =BS!B4 -> Particular | D3: =BS!D4 -> 2022 | E3: =BS!E4 -> 2023 | F3: =BS!F4 -> 2024 | G3: =BS!G4 -> 2025 | H3: =BS!H4 -> 2026
B4: All Values In Crores
B6: INCOME
B7: Revenue from operations | D7: 52446 | E7: 60580 | F7: 61896 | G7: 63121 | H7: 64468
B8: Other income | D8: 258 | E8: 512 | F8: 811 | G8: 1017 | H8: 751
B9: TOTAL INCOME | D9: =SUM(D7:D8) -> 52704 | E9: =SUM(E7:E8) -> 61092 | F9: =SUM(F7:F8) -> 62707 | G9: =SUM(G7:G8) -> 64138 | H9: =SUM(H7:H8) -> 65219
B11: EXPENSES
B12: Cost of materials consumed | D12: 16446 | E12: 20212 | F12: 19257 | G12: 19458 | H12: 20981
B13: Purchases of stock-in-trade | D13: 9311 | E13: 11579 | F13: 10514 | G13: 11273 | H13: 11113
B14: Changes in inventories of finished goods, Stock-in-Trade and work-in-progress | D14: -22 | E14: -75 | F14: -11 | G14: -153 | H14: -429
B15: Employee benefits expense | D15: 2545 | E15: 2854 | F15: 3009 | G15: 3077 | H15: 3175
B16: Finance costs | D16: 106 | E16: 114 | F16: 334 | G16: 395 | H16: 410
B17: Depreciation and amortisation expense | D17: 1091 | E17: 1137 | F17: 1216 | G17: 1355 | H17: 1333
B18: Other expenses | D18: 11309 | E18: 11861 | F18: 14464 | G18: 14615 | H18: 14574
B19: TOTAL EXPENSES | D19: =SUM(D12:D18) -> 40786 | E19: =SUM(E12:E18) -> 47682 | F19: =SUM(F12:F18) -> 48783 | G19: =SUM(G12:G18) -> 50020 | H19: =SUM(H12:H18) -> 51157
B21: Profit before Exceptional Items and tax and before share of equity accounted TRUSTEE | D21: =D9-D19 -> 11918 | E21: =E9-E19 -> 13410 | F21: =F9-F19 -> 13924 | G21: =G9-G19 -> 14118 | H21: =H9-H19 -> 14062
B23: Share of loss of equity accounted investee net of tax | D23: 0 | E23: -1 | F23: -4 | G23: -8 | H23: -15
B24: Profit before exceptional items and tax | D24: =SUM(D21:D23) -> 11918 | E24: =SUM(E21:E23) -> 13409 | F24: =SUM(F21:F23) -> 13920 | G24: =SUM(G21:G23) -> 14110 | H24: =SUM(H21:H23) -> 14047
B25: Exceptional items (net) | D25: -44 | E25: -64 | F25: 6 | G25: 305 | H25: -235
B27: Profit before tax from Continuing Operations | D27: =SUM(D24:D25) -> 11874 | E27: =SUM(E24:E25) -> 13345 | F27: =SUM(F24:F25) -> 13926 | G27: =SUM(G24:G25) -> 14415 | H27: =SUM(H24:H25) -> 13812
B29: Tax expenses
B30: Current tax | D30: -2840 | E30: -3001 | F30: -3521 | G30: -3620 | H30: -3163
B31: Deferred tax charge | D31: -147 | E31: -200 | F31: -123 | G31: -124 | H31: 3
B32: Profit after tax from Continuing Operations (A) | D32: =SUM(D27:D31) -> 8887 | E32: =SUM(E27:E31) -> 10144 | F32: =SUM(F27:F31) -> 10282 | G32: =SUM(G27:G31) -> 10671 | H32: =SUM(H27:H31) -> 10652
B34: Profit/(Loss) from discontinued operations before tax | D34: 3 | E34: -1 | F34: 0 | G34: 0 | H34: 0
B35: Tax adjustment of discontinued operations | D35: 2 | E35: 0 | F35: 0 | G35: 0 | H35: 0
B36: Profit/(Loss) from discontinued operations after tax (B) | D36: =SUM(D34:D35) -> 5 | E36: =SUM(E34:E35) -> -1 | F36: =SUM(F34:F35) -> 0 | G36: =SUM(G34:G35) -> 0 | H36: =SUM(H34:H35) -> 0
B38: PROFIT FOR THE YEAR (A+B) | D38: =D32+D36 -> 8892 | E38: =E32+E36 -> 10143 | F38: =F32+F36 -> 10282 | G38: =G32+G36 -> 10671 | H38: =H32+H36 -> 10652

Sheet Company Data
B2: =Model!B2 -> Hindustan Uniliver Ltd
B3: =Model!B3 -> HINDUNILVR | 500696
B4: =Model!B4 -> Financial Statement & DCF Analysis
B7: S.No. | C7: Company | D7: CMP Rs. | E7: Mar Cap Rs.Cr. | F7: Shares (MM) | G7: Debt Rs.Cr. | H7: EV Rs.Cr. | I7: Sales Rs.Cr. | J7: EBITDA | K7: EV / EBITDA | L7: P/E | M7: PAT 12M Rs.Cr. | N7: Cash Rs.Cr. | O7: Cash Beginning Rs.Cr. | P7: OP 12M Rs.Cr. | Q7: Tax 12M Rs.Cr. | R7: Current Tax 12M Rs.Cr. | S7: Tax Rate
B8: 1 | C8: Hind. Unilever | D8: 1932 | E8: 453941.03 | F8: =E8/D8 -> 234.95913 | G8: 1478 | H8: =E8+G8-N8 -> 452171.03 | I8: 66052 | J8: 15039 | K8: =H8/J8 -> 30.066562 | L8: 41.16 | M8: 11027.55 | N8: 3248 | O8: 6070 | P8: 15347 | Q8: 3586 | R8: 3617 | S8: 0.25
B9: 2 | C9: ITC | D9: 262.3 | E9: 328675.46 | F9: =E9/D9 -> 1253.0517 | G9: 2399.06 | H9: =E9+G9-N9 -> 328065.73 | I9: 76487.98 | J9: 27306 | K9: =H9/J9 -> 12.014419 | L9: 16.64 | M9: 19748.27 | N9: 3008.79 | O9: 622.38 | P9: 25682.3 | Q9: 6582.7 | R9: 6032.73 | S9: 0.25
B10: 3 | C10: Hindustan Foods | D10: 625.7 | E10: 7581.15 | F10: =E10/D10 -> 12.11627 | G10: 1088.26 | H10: =E10+G10-N10 -> 8617.7 | I10: 4400.19 | J10: 363 | K10: =H10/J10 -> 23.74022 | L10: 46.87 | M10: 161.76 | N10: 51.71 | O10: 79.78 | P10: 380.49 | Q10: 53.48 | R10: 45.51 | S10: 0.25
B11: 4 | C11: Godavari Bioref. | D11: 241.01 | E11: 1233.39 | F11: =E11/D11 -> 5.1175885 | G11: 530.76 | H11: =E11+G11-N11 -> 1732 | I11: 2012.58 | J11: 127 | K11: =H11/J11 -> 13.637795 | L11: 42.52 | M11: 29.01 | N11: 32.15 | O11: 12.25 | P11: 121.88 | Q11: 0.79 | R11: 0.91 | S11: 0.23
S23: 0.23

Sheet CF
B3: ='P&L'!B3 -> Particular | D3: ='P&L'!D3 -> 2022 | E3: ='P&L'!E3 -> 2023 | F3: ='P&L'!F3 -> 2024 | G3: ='P&L'!G3 -> 2025 | H3: ='P&L'!H3 -> 2026
B4: All Values In Crores
B6: A CASH FLOWS FROM OPERATING ACTIVITIES:
B7: Profit before tax from continuing operations and before share of equity accounted investee | D7: 11874 | E7: 13346 | F7: 13926 | G7: 14415 | H7: 13812
B8: Profit / (loss) before tax from discontinued operations | D8: 0 | E8: 0 | F8: 0 | G8: 0 | H8: 4336
B9: Adjustments for:
B10: Depreciation and amortisation expenses | D10: 1106 | E10: 1152 | F10: 1216 | G10: 1363 | H10: 1436
B11: (Profit)/loss on sale of property, plant and equipment | D11: -97 | E11: -100 | F11: 18 | G11: 43 | H11: 40
B12: Contingent consideration true up for business combination | D12: -9 | E12: -2 | F12: 0 | G12: 0 | H12: 0
B13: Fair value gain on financial liability on acquisition | D13: 0 | E13: 0 | F13: -132 | G13: 120 | H13: 502
B14: Finance Income | D14: -198 | E14: -411 | F14: -546 | G14: -755 | H14: -546
B15: Dividend income | D15: -1 | E15: -2 | F15: -3 | G15: 0 | H15: -5
B16: Other non operating income – Fair value gain on investments | D16: -59 | E16: -99 | F16: -249 | G16: -256 | H16: -195
B17: Profit on sale of stake in joint venture | D17: 0 | E17: 0 | F17: 0 | G17: 0 | H17: -256
B18: Interest expense | D18: 106 | E18: 114 | F18: 317 | G18: 372 | H18: 424
B19: Movement in provision towards litigation | D19: 0 | E19: 0 | F19: -159 | G19: -595 | H19: 0
B20: Provision for expenses on employee stock options | D20: -1 | E20: 1 | F20: 0 | G20: 0 | H20: 0
B21: Profit on sale of brand rights | D21: -29 | E21: -60 | F21: 0 | G21: -1 | H21: 0
... B28: Mark-to-market (gain)/ loss on derivative financial instruments | D28: -4 | E28: -8 | F28: -10 | G28: 4 | H28: -105
B29: Subtotal of Adjustments | D29: =SUM(D10:D28) -> 955 | E29: =SUM(E10:E28) -> 743 | F29: =SUM(F10:F28) -> 611 | G29: =SUM(G10:G28) -> 527 | H29: =SUM(H10:H28) -> -2995
B31: Cash Generated from operations before working capital changes | D31: =SUM(D7:D28) -> 12829 | E31: =SUM(E7:E28) -> 14089 | F31: =SUM(F7:F28) -> 14537 | G31: =SUM(G7:G28) -> 14942 | H31: =SUM(H7:H28) -> 15153
B33: Adjustments for:
B34: (Increase)/decrease in Non-Current Assets | D34: 3 | E34: -14 | F34: -30 | G34: -87 | H34: 10
B35: (Increase)/decrease in Current Assets | D35: -480 | E35: -1111 | F35: 220 | G35: -1275 | H35: 76
B36: (Increase)/decrease in Inventories | D36: -758 | E36: -339 | F36: 74 | G36: -584 | H36: -692
B37: Increase/(decrease) in Non-Current Liabilities | D37: 86 | E37: -116 | F37: 128 | G37: -284 | H37: -184
B38: Increase/(decrease) in Current Liabilities | D38: 149 | E38: 622 | F38: 921 | G38: 1442 | H38: 1476
B39: Cash flows generated from operations | D39: =SUM(D31:D38) -> 11829 | E39: =SUM(E31:E38) -> 13131 | F39: =SUM(F31:F38) -> 15850 | G39: =SUM(G31:G38) -> 14154 | H39: =SUM(H31:H38) -> 15839
B41: Taxes paid (net of refunds) | D41: -2784 | E41: -3138 | F41: -381 | G41: -2268 | H41: -4840
B42: Profit/(Loss) from Joint venture | D42: 0 | E42: -1 | F42: 0 | G42: 0 | H42: 0
B43: Profit/(Loss) from discontinued operations | D43: 3 | E43: -1 | F43: 0 | G43: 0 | H43: 0
B45: Net cash flows generated from operating activities - [A] | D45: =SUM(D39:D43) -> 9048 | E45: =SUM(E39:E43) -> 9991 | F45: =SUM(F39:F43) -> 15469 | G45: =SUM(G39:G43) -> 11886 | H45: =SUM(H39:H43) -> 10999
B47: B CASH FLOWS FROM INVESTING ACTIVITIES:
B48: Purchase of property, plant and equipment | D48: -1225 | E48: -1174 | F48: -1468 | G48: -1254 | H48: -1258
B49: Sale proceeds of property, plant and equipment | D49: 146 | E49: 121 | F49: 20 | G49: 13 | H49: 29
B50: Purchase of non-current investments | D50: 0 | E50: 0 | F50: 0 | G50: 0 | H50: -112
B51: Sale proceeds of non-current investments | D51: 0 | E51: 0 | F51: 0 | G51: 0 | H51: 1
B52: Purchase of intangible assets | D52: -3 | E52: -18 | F52: -9 | G52: -21 | H52: -103
B53: Sale proceeds of intangible assets (brand rights) | D53: 29 | E53: 60 | F53: 0 | G53: 595 | H53: 0
B54: Investment in subsidiary | D54: 0 | E54: -264 | F54: 0 | G54: 0 | H54: 0
...
